Workbook

Sheet Cover
A1: Farm financial model — structure (Stage 1)
A2: Generated 2026-10-19 by scripts/build_financial_model.py
A4: Status | B4: STRUCTURE AND PLACEHOLDERS. Inputs labelled A or U are placeholders, not findings. Do not quote outputs as forecasts.
A5: Purpose | B5: Tests whether each farm model fits the founder's capital, when cash turns positive, and which assumptions matter most.
A6: Terms | B6: Real terms (constant 2026 RWF, no inflation). Month 1 = first month of spending. A farm year = 12 model months.
A7: How to use | B7: Pick a scenario and a farm model on Control. Edit only blue cells. Results are on Metrics; detail on Annual and CashFlow.
A8: Legend: blue | B8: Input you may edit (Control, Assumptions, Models, Curves, Sensitivity).
A9: Legend: black | B9: Formula. Do not overwrite.
A10: Legend: green | B10: Direct link to another sheet.
A11: Legend: yellow fill | B11: Key inputs to confirm with the founder.
A12: Labels | B12: V verified (source ID) · E estimate (method shown) · A assumption · U unknown. See CLAUDE.md.
A13: Structural constants | B13: Sale age 9 months · first-birth lag 6 months · receivable lag 1 month. Change them in the script and rebuild.
A14: Not modelled yet | B14: Loans and interest, inflation, tax losses carried forward, terminal value of orchards, value-added processing, agritourism.
A15: Sheets | B15: Control · Assumptions · Models · Curves · Sensitivity · Land · Trees · Livestock · Feed · CapEx · CashFlow · Annual · Metrics

Sheet Control
A1: Control
A2: The two switches and the founder's key inputs. Blue cells only.
A4: Key | B4: Input | C4: Value | D4: Unit | E4: Note
A5: scenario | B5: Scenario (1 downside · 2 base · 3 upside) | C5: 2 | D5: index | E5: Drives every Assumptions row
A6: model | B6: Farm model (1 M1 · 2 M2 · 3 M3) | C6: 1 | D6: index | E6: Drives every Models row
A7: area | B7: Total farm area | C7: 5 | D7: ha | E7: [A] founder: 2–10 ha; base 5 ha until surveyed
A8: capital | B8: Capital available, years 1–2 | C8: 35000000 | D8: RWF | E8: [A] founder: under USD 25k
A9: start_year | B9: Model start year | C9: 2026 | D9: year | E9: Month 1 = first month of spending
A10: start_month | B10: Model start month (1–12) | C10: 11 | D10: month | E10: 11 = November
A11: plant_m | B11: Tree planting month (model month #) | C11: 5 | D11: month # | E11: [A] 5 = March 2027, Season B onset
A12: past_m | B12: Pasture/fodder planting month (model month #) | C12: 5 | D12: month # | E12: [A] same rains as trees
B14: Selected scenario | C14: =CHOOSE(Control!$C$5,"Downside","Base","Upside")
B15: Selected farm model | C15: =CHOOSE(Control!$C$6,"M1 Conservative mixed","M2 Diversified commercial","M3 Tech-enabled integrated")
B16: Capital available in USD (at the Assumptions rate) | C16: =Control!$C$8/Assumptions!$H$6

Sheet Assumptions
A1: Assumptions
A2: Uncertain inputs with downside / base / upside values. Selected = the value for the scenario chosen on Control.
A4: ID | B4: Group | C4: Parameter | D4: Unit | E4: Downside | F4: Base | G4: Upside | H4: Selected | I4: Label | J4: Source | K4: Notes
B5: General
A6: FX | B6: General | C6: Exchange rate | D6: RWF per USD | E6: 1470 | F6: 1470 | G6: 1470 | H6: =CHOOSE(Control!$C$5,E6,F6,G6) | I6: A | J6: placeholder — pending Stage 1 research | K6: Verify against the BNR reference rate
A7: DR | B7: General | C7: Real discount rate | D7: per year | E7: 0.14 | F7: 0.12 | G7: 0.1 | H7: =CHOOSE(Control!$C$5,E7,F7,G7) | I7: A | J7: judgement | K7: Real terms: the model is in constant 2026 RWF
A8: TAX | B8: General | C8: Income tax rate on profit | D8: share | E8: 0.28 | F8: 0.28 | G8: 0.28 | H8: =CHOOSE(Control!$C$5,E8,F8,G8) | I8: U | J8: placeholder — pending Stage 1 research | K8: Confirm agricultural income treatment with RRA
A9: CREDIT | B9: General | C9: Share of sales on credit | D9: share | E9: 0.6 | F9: 0.5 | G9: 0.3 | H9: =CHOOSE(Control!$C$5,E9,F9,G9) | I9: A | J9: judgement | K9: Collected 1 month later
A10: CONT | B10: General | C10: Capex contingency | D10: share of capex | E10: 0.15 | F10: 0.1 | G10: 0.08 | H10: =CHOOSE(Control!$C$5,E10,F10,G10) | I10: A | J10: judgement
A11: MKTG | B11: General | C11: Marketing and sales cost | D11: share of sales | E11: 0.03 | F11: 0.02 | G11: 0.02 | H11: =CHOOSE(Control!$C$5,E11,F11,G11) | I11: A | J11: judgement
A12: RM | B12: General | C12: Repairs and maintenance | D12: share of capex per yr | E12: 0.05 | F12: 0.04 | G12: 0.03 | H12: =CHOOSE(Control!$C$5,E12,F12,G12) | I12: A | J12: judgement
B13: Labour
A14: WAGE | B14: Labour | C14: Permanent worker wage | D14: RWF per month | E14: 60000 | F14: 50000 | G14: 45000 | H14: =CHOOSE(Control!$C$5,E14,F14,G14) | I14: A | J14: placeholder — pending Stage 1 research
A15: DAYWAGE | B15: Labour | C15: Casual labour wage | D15: RWF per day | E15: 2500 | F15: 2000 | G15: 1800 | H15: =CHOOSE(Control!$C$5,E15,F15,G15) | I15: A | J15: placeholder — pending Stage 1 research
A16: DAYS_HA | B16: Labour | C16: Casual labour in orchard | D16: days per ha per yr | E16: 120 | F16: 100 | G16: 80 | H16: =CHOOSE(Control!$C$5,E16,F16,G16) | I16: A | J16: placeholder — pending Stage 1 research
B17: Capital costs
A18: FENCE | B18: Capital costs | C18: Perimeter fence | D18: RWF per m | E18: 6000 | F18: 5000 | G18: 4000 | H18: =CHOOSE(Control!$C$5,E18,F18,G18) | I18: A | J18: placeholder — pending Stage 1 research
A19: IFENCE | B19: Capital costs | C19: Internal paddock fence | D19: RWF per m | E19: 3500 | F19: 3000 | G19: 2500 | H19: =CHOOSE(Control!$C$5,E19,F19,G19) | I19: A | J19: placeholder — pending Stage 1 research
A20: GATE | B20: Capital costs | C20: Gate | D20: RWF each | E20: 250000 | F20: 200000 | G20: 150000 | H20: =CHOOSE(Control!$C$5,E20,F20,G20) | I20: A | J20: placeholder — pending Stage 1 research
A21: TANK | B21: Capital costs | C21: Water storage | D21: RWF per m3 | E21: 120000 | F21: 100000 | G21: 90000 | H21: =CHOOSE(Control!$C$5,E21,F21,G21) | I21: A | J21: placeholder — pending Stage 1 research
A22: GUTTER | B22: Capital costs | C22: Rainwater harvesting fittings | D22: RWF lump | E22: 400000 | F22: 300000 | G22: 250000 | H22: =CHOOSE(Control!$C$5,E22,F22,G22) | I22: A | J22: placeholder — pending Stage 1 research
A23: BORE | B23: Capital costs | C23: Borehole (if legal and viable) | D23: RWF lump | E23: 12000000 | F23: 9000000 | G23: 7000000 | H23: =CHOOSE(Control!$C$5,E23,F23,G23) | I23: U | J23: placeholder — pending Stage 1 research | K23: Hydrogeology and permit unknown
A24: PUMP | B24: Capital costs | C24: Solar pump system | D24: RWF lump | E24: 4500000 | F24: 3500000 | G24: 3000000 | H24: =CHOOSE(Control!$C$5,E24,F24,G24) | I24: A | J24: placeholder — pending Stage 1 research
A25: DRIP | B25: Capital costs | C25: Drip irrigation | D25: RWF per ha | E25: 4500000 | F25: 3500000 | G25: 3000000 | H25: =CHOOSE(Control!$C$5,E25,F25,G25) | I25: A | J25: placeholder — pending Stage 1 research
A26: PAST_EST | B26: Capital costs | C26: Pasture establishment | D26: RWF per ha | E26: 600000 | F26: 450000 | G26: 350000 | H26: =CHOOSE(Control!$C$5,E26,F26,G26) | I26: A | J26: placeholder — pending Stage 1 research
A27: FOD_EST | B27: Capital costs | C27: Fodder bank establishment | D27: RWF per ha | E27: 900000 | F27: 700000 | G27: 550000 | H27: =CHOOSE(Control!$C$5,E27,F27,G27) | I27: A | J27: placeholder — pending Stage 1 research
A28: HOUSE | B28: Capital costs | C28: Animal house | D28: RWF per m2 | E28: 60000 | F28: 45000 | G28: 35000 | H28: =CHOOSE(Control!$C$5,E28,F28,G28) | I28: A | J28: placeholder — pending Stage 1 research
A29: M2HEAD | B29: Capital costs | C29: House floor area per adult animal | D29: m2 per head | E29: 1.5 | F29: 1.2 | G29: 1 | H29: =CHOOSE(Control!$C$5,E29,F29,G29) | I29: A | J29: placeholder — pending Stage 1 research
A30: QUAR | B30: Capital costs | C30: Quarantine pen and handling race | D30: RWF lump | E30: 800000 | F30: 600000 | G30: 500000 | H30: =CHOOSE(Control!$C$5,E30,F30,G30) | I30: A | J30: placeholder — pending Stage 1 research
A31: SOIL | B31: Capital costs | C31: Soil test | D31: RWF per sample | E31: 40000 | F31: 30000 | G31: 25000 | H31: =CHOOSE(Control!$C$5,E31,F31,G31) | I31: U | J31: placeholder — pending Stage 1 research | K31: Get lab quotes
A32: WATER | B32: Capital costs | C32: Water test | D32: RWF per sample | E32: 60000 | F32: 45000 | G32: 35000 | H32: =CHOOSE(Control!$C$5,E32,F32,G32) | I32: U | J32: placeholder — pending Stage 1 research | K32: Get lab quotes
A33: SURVEY | B33: Capital costs | C33: Survey, title and legal checks | D33: RWF lump | E33: 600000 | F33: 400000 | G33: 300000 | H33: =CHOOSE(Control!$C$5,E33,F33,G33) | I33: U | J33: placeholder — pending Stage 1 research
A34: PERMIT | B34: Capital costs | C34: Permits and compliance | D34: RWF lump | E34: 500000 | F34: 300000 | G34: 200000 | H34: =CHOOSE(Control!$C$5,E34,F34,G34) | I34: U | J34: placeholder — pending Stage 1 research
A35: PROF | B35: Capital costs | C35: Professional set-up visits (agronomist, vet) | D35: RWF lump | E35: 1000000 | F35: 800000 | G35: 600000 | H35: =CHOOSE(Control!$C$5,E35,F35,G35) | I35: A | J35: placeholder — pending Stage 1 research
A36: PV | B36: Capital costs | C36: Solar PV with battery | D36: RWF per kWp | E36: 2500000 | F36: 2000000 | G36: 1700000 | H36: =CHOOSE(Control!$C$5,E36,F36,G36) | I36: A | J36: placeholder — pending Stage 1 research
A37: SCALE | B37: Capital costs | C37: Livestock weighing scale | D37: RWF lump | E37: 600000 | F37: 450000 | G37: 350000 | H37: =CHOOSE(Control!$C$5,E37,F37,G37) | I37: A | J37: placeholder — pending Stage 1 research
B38: Operating costs
A39: VET | B39: Operating costs | C39: Veterinary care and medicines | D39: RWF per head per yr | E39: 8000 | F39: 6000 | G39: 5000 | H39: =CHOOSE(Control!$C$5,E39,F39,G39) | I39: A | J39: placeholder — pending Stage 1 research | K39: Confirm with a Rwandan vet
A40: MINERAL | B40: Operating costs | C40: Minerals and supplements | D40: RWF per head per yr | E40: 3000 | F40: 2500 | G40: 2000 | H40: =CHOOSE(Control!$C$5,E40,F40,G40) | I40: A | J40: placeholder — pending Stage 1 research
A41: FERT | B41: Operating costs | C41: Orchard inputs (fertiliser, compost, protection) | D41: RWF per ha per yr | E41: 900000 | F41: 700000 | G41: 550000 | H41: =CHOOSE(Control!$C$5,E41,F41,G41) | I41: A | J41: placeholder — pending Stage 1 research
...

Sheet Models
A1: Models
A2: What defines each farm model. Selected = the column for the model chosen on Control.
A4: ID | B4: Group | C4: Parameter | D4: Unit | E4: M1 | F4: M2 | G4: M3 | H4: Selected | I4: Label | J4: Notes
B5: Land use (share of total area)
A6: Z01 | B6: Land use (share of total area) | C6: Z0+Z1 base, store, nursery | D6: share | E6: 0.05 | F6: 0.05 | G6: 0.07 | H6: =CHOOSE(Control!$C$6,E6,F6,G6) | I6: A | J6: See zoning-concept.md
A7: Z2 | B7: Land use (share of total area) | C7: Z2 orchard | D7: share | E7: 0.25 | F7: 0.35 | G7: 0.38 | H7: =CHOOSE(Control!$C$6,E7,F7,G7) | I7: A
A8: Z3 | B8: Land use (share of total area) | C8: Z3 paddocks and fodder bank | D8: share | E8: 0.5 | F8: 0.4 | G8: 0.35 | H8: =CHOOSE(Control!$C$6,E8,F8,G8) | I8: A
A9: Z4 | B9: Land use (share of total area) | C9: Z4 boundary and shelter trees | D9: share | E9: 0.1 | F9: 0.1 | G9: 0.1 | H9: =CHOOSE(Control!$C$6,E9,F9,G9) | I9: A
A10: Z5 | B10: Land use (share of total area) | C10: Z5 lake/wetland buffer, steep, conservation | D10: share | E10: 0.1 | F10: 0.1 | G10: 0.1 | H10: =CHOOSE(Control!$C$6,E10,F10,G10) | I10: U | J10: Depends on shoreline and survey
A11: FODDER | B11: Land use (share of total area) | C11: Fodder bank share of Z3 | D11: share | E11: 0.3 | F11: 0.3 | G11: 0.35 | H11: =CHOOSE(Control!$C$6,E11,F11,G11) | I11: A
B12: Orchard mix (share of Z2)
A13: OR_AVO | B13: Orchard mix (share of Z2) | C13: Avocado | D13: share | E13: 1 | F13: 0.5 | G13: 0.4 | H13: =CHOOSE(Control!$C$6,E13,F13,G13) | I13: A | J13: Pending site suitability
A14: OR_MAN | B14: Orchard mix (share of Z2) | C14: Mango | D14: share | E14: 0 | F14: 0 | G14: 0.1 | H14: =CHOOSE(Control!$C$6,E14,F14,G14) | I14: A
A15: OR_PAS | B15: Orchard mix (share of Z2) | C15: Passion fruit | D15: share | E15: 0 | F15: 0.3 | G15: 0.2 | H15: =CHOOSE(Control!$C$6,E15,F15,G15) | I15: A
A16: OR_PAP | B16: Orchard mix (share of Z2) | C16: Papaya | D16: share | E16: 0 | F16: 0.2 | G16: 0.1 | H16: =CHOOSE(Control!$C$6,E16,F16,G16) | I16: A
A17: OR_TTO | B17: Orchard mix (share of Z2) | C17: Tree tomato | D17: share | E17: 0 | F17: 0 | G17: 0.1 | H17: =CHOOSE(Control!$C$6,E17,F17,G17) | I17: A
A18: OR_CIT | B18: Orchard mix (share of Z2) | C18: Citrus | D18: share | E18: 0 | F18: 0 | G18: 0.1 | H18: =CHOOSE(Control!$C$6,E18,F18,G18) | I18: A
A19: OR_MAC | B19: Orchard mix (share of Z2) | C19: Macadamia | D19: share | E19: 0 | F19: 0 | G19: 0 | H19: =CHOOSE(Control!$C$6,E19,F19,G19) | I19: A
B20: Livestock introduction
A21: GT_T1M | B21: Livestock introduction | C21: Goats tranche 1: month | D21: month # | E21: 9 | F21: 9 | G21: 9 | H21: =CHOOSE(Control!$C$6,E21,F21,G21) | I21: A | J21: After fencing, water, house and forage
A22: GT_T1F | B22: Livestock introduction | C22: Goats tranche 1: breeding females | D22: head | E22: 15 | F22: 20 | G22: 25 | H22: =CHOOSE(Control!$C$6,E22,F22,G22) | I22: A
A23: GT_T1MALE | B23: Livestock introduction | C23: Goats tranche 1: breeding males | D23: head | E23: 1 | F23: 1 | G23: 1 | H23: =CHOOSE(Control!$C$6,E23,F23,G23) | I23: A
A24: GT_T2M | B24: Livestock introduction | C24: Goats tranche 2: month | D24: month # | E24: 18 | F24: 18 | G24: 18 | H24: =CHOOSE(Control!$C$6,E24,F24,G24) | I24: A | J24: After quarantine and first results
A25: GT_T2F | B25: Livestock introduction | C25: Goats tranche 2: breeding females | D25: head | E25: 10 | F25: 15 | G25: 20 | H25: =CHOOSE(Control!$C$6,E25,F25,G25) | I25: A
A26: GT_T2MALE | B26: Livestock introduction | C26: Goats tranche 2: breeding males | D26: head | E26: 0 | F26: 1 | G26: 1 | H26: =CHOOSE(Control!$C$6,E26,F26,G26) | I26: A
A27: GT_TARGET | B27: Livestock introduction | C27: Goats: target breeding females | D27: head | E27: 40 | F27: 50 | G27: 60 | H27: =CHOOSE(Control!$C$6,E27,F27,G27) | I27: A | J27: Check against the feed balance
A28: SH_T1M | B28: Livestock introduction | C28: Sheep tranche 1: month | D28: month # | E28: 0 | F28: 12 | G28: 12 | H28: =CHOOSE(Control!$C$6,E28,F28,G28) | I28: A | J28: 0 = no sheep
A29: SH_T1F | B29: Livestock introduction | C29: Sheep tranche 1: breeding females | D29: head | E29: 0 | F29: 10 | G29: 15 | H29: =CHOOSE(Control!$C$6,E29,F29,G29) | I29: A
A30: SH_T1MALE | B30: Livestock introduction | C30: Sheep tranche 1: breeding males | D30: head | E30: 0 | F30: 1 | G30: 1 | H30: =CHOOSE(Control!$C$6,E30,F30,G30) | I30: A
A31: SH_T2M | B31: Livestock introduction | C31: Sheep tranche 2: month | D31: month # | E31: 0 | F31: 0 | G31: 24 | H31: =CHOOSE(Control!$C$6,E31,F31,G31) | I31: A | J31: 0 = none
A32: SH_T2F | B32: Livestock introduction | C32: Sheep tranche 2: breeding females | D32: head | E32: 0 | F32: 0 | G32: 10 | H32: =CHOOSE(Control!$C$6,E32,F32,G32) | I32: A
A33: SH_T2MALE | B33: Livestock introduction | C33: Sheep tranche 2: breeding males | D33: head | E33: 0 | F33: 0 | G33: 0 | H33: =CHOOSE(Control!$C$6,E33,F33,G33) | I33: A
A34: SH_TARGET | B34: Livestock introduction | C34: Sheep: target breeding females | D34: head | E34: 0 | F34: 20 | G34: 30 | H34: =CHOOSE(Control!$C$6,E34,F34,G34) | I34: A
B35: Livestock management
A36: RETAIN | B36: Livestock management | C36: Share of female young kept as replacements (while below target) | D36: share | E36: 0.6 | F36: 0.5 | G36: 0.5 | H36: =CHOOSE(Control!$C$6,E36,F36,G36) | I36: A
A37: BSHARE | B37: Livestock management | C37: Share of young stock sold as breeding stock | D37: share | E37: 0 | F37: 0.1 | G37: 0.2 | H37: =CHOOSE(Control!$C$6,E37,F37,G37) | I37: A | J37: Needs records and genetics
A38: CONSERVE | B38: Livestock management | C38: Share of surplus forage conserved (hay/silage) | D38: share | E38: 0.3 | F38: 0.5 | G38: 0.7 | H38: =CHOOSE(Control!$C$6,E38,F38,G38) | I38: A
B39: Operations
A40: WORKERS | B40: Operations | C40: Permanent workers | D40: people | E40: 1 | F40: 2 | G40: 3 | H40: =CHOOSE(Control!$C$6,E40,F40,G40) | I40: A
B41: Capital items
...

Sheet Curves
A1: Curves
A2: Yield per plant by farm year, harvest seasonality by calendar month, pasture growth by month.
A4: ID | B4: Crop | C4: Unit | D4: Y1 | E4: Y2 | F4: Y3 | G4: Y4 | H4: Y5 | I4: Y6 | J4: Y7 | K4: Y8 | L4: Y9 | M4: Y10 | N4: Label | O4: Source / note
A5: AVO_CURVE | B5: Avocado (grafted) | C5: kg per plant | D5: 0 | E5: 0 | F5: 5 | G5: 15 | H5: 30 | I5: 50 | J5: 70 | K5: 90 | L5: 100 | M5: 110 | N5: A | O5: placeholder — pending Stage 1 research. Planted in year 1; short-cycle crops repeat their first years.
A6: MAN_CURVE | B6: Mango (grafted) | C6: kg per plant | D6: 0 | E6: 0 | F6: 5 | G6: 15 | H6: 30 | I6: 45 | J6: 60 | K6: 75 | L6: 90 | M6: 100 | N6: A | O6: placeholder — pending Stage 1 research. Planted in year 1; short-cycle crops repeat their first years.
A7: PAS_CURVE | B7: Passion fruit | C7: kg per plant | D7: 2 | E7: 10 | F7: 6 | G7: 0 | H7: 0 | I7: 0 | J7: 0 | K7: 0 | L7: 0 | M7: 0 | N7: A | O7: placeholder — pending Stage 1 research. Planted in year 1; short-cycle crops repeat their first years.
A8: PAP_CURVE | B8: Papaya | C8: kg per plant | D8: 5 | E8: 30 | F8: 20 | G8: 0 | H8: 0 | I8: 0 | J8: 0 | K8: 0 | L8: 0 | M8: 0 | N8: A | O8: placeholder — pending Stage 1 research. Planted in year 1; short-cycle crops repeat their first years.
A9: TTO_CURVE | B9: Tree tomato | C9: kg per plant | D9: 0 | E9: 10 | F9: 15 | G9: 10 | H9: 0 | I9: 0 | J9: 0 | K9: 0 | L9: 0 | M9: 0 | N9: A | O9: placeholder — pending Stage 1 research. Planted in year 1; short-cycle crops repeat their first years.
A10: CIT_CURVE | B10: Citrus | C10: kg per plant | D10: 0 | E10: 0 | F10: 5 | G10: 15 | H10: 30 | I10: 45 | J10: 60 | K10: 70 | L10: 80 | M10: 90 | N10: A | O10: placeholder — pending Stage 1 research. Planted in year 1; short-cycle crops repeat their first years.
A11: MAC_CURVE | B11: Macadamia (nut in shell) | C11: kg per plant | D11: 0 | E11: 0 | F11: 0 | G11: 1 | H11: 3 | I11: 6 | J11: 9 | K11: 12 | L11: 15 | M11: 18 | N11: A | O11: placeholder — pending Stage 1 research. Planted in year 1; short-cycle crops repeat their first years.
A14: ID | B14: Crop | C14: Unit | D14: Jan | E14: Feb | F14: Mar | G14: Apr | H14: May | I14: Jun | J14: Jul | K14: Aug | L14: Sep | M14: Oct | N14: Nov | O14: Dec | P14: Sum (must be 1) | Q14: Label | R14: Note
A15: AVO_SEASON | B15: Avocado (grafted) | C15: share of year | D15: 0.083333 | E15: 0.083333 | F15: 0.083333 | G15: 0.083333 | H15: 0.083333 | I15: 0.083333 | J15: 0.083333 | K15: 0.083333 | L15: 0.083333 | M15: 0.083333 | N15: 0.083333 | O15: 0.083337 | P15: =SUM(D15:O15) | Q15: A | R15: Uniform until the Rwandan harvest calendar is sourced
A16: MAN_SEASON | B16: Mango (grafted) | C16: share of year | D16: 0.083333 | E16: 0.083333 | F16: 0.083333 | G16: 0.083333 | H16: 0.083333 | I16: 0.083333 | J16: 0.083333 | K16: 0.083333 | L16: 0.083333 | M16: 0.083333 | N16: 0.083333 | O16: 0.083337 | P16: =SUM(D16:O16) | Q16: A | R16: Uniform until the Rwandan harvest calendar is sourced
A17: PAS_SEASON | B17: Passion fruit | C17: share of year | D17: 0.083333 | E17: 0.083333 | F17: 0.083333 | G17: 0.083333 | H17: 0.083333 | I17: 0.083333 | J17: 0.083333 | K17: 0.083333 | L17: 0.083333 | M17: 0.083333 | N17: 0.083333 | O17: 0.083337 | P17: =SUM(D17:O17) | Q17: A | R17: Uniform until the Rwandan harvest calendar is sourced
A18: PAP_SEASON | B18: Papaya | C18: share of year | D18: 0.083333 | E18: 0.083333 | F18: 0.083333 | G18: 0.083333 | H18: 0.083333 | I18: 0.083333 | J18: 0.083333 | K18: 0.083333 | L18: 0.083333 | M18: 0.083333 | N18: 0.083333 | O18: 0.083337 | P18: =SUM(D18:O18) | Q18: A | R18: Uniform until the Rwandan harvest calendar is sourced
A19: TTO_SEASON | B19: Tree tomato | C19: share of year | D19: 0.083333 | E19: 0.083333 | F19: 0.083333 | G19: 0.083333 | H19: 0.083333 | I19: 0.083333 | J19: 0.083333 | K19: 0.083333 | L19: 0.083333 | M19: 0.083333 | N19: 0.083333 | O19: 0.083337 | P19: =SUM(D19:O19) | Q19: A | R19: Uniform until the Rwandan harvest calendar is sourced
A20: CIT_SEASON | B20: Citrus | C20: share of year | D20: 0.083333 | E20: 0.083333 | F20: 0.083333 | G20: 0.083333 | H20: 0.083333 | I20: 0.083333 | J20: 0.083333 | K20: 0.083333 | L20: 0.083333 | M20: 0.083333 | N20: 0.083333 | O20: 0.083337 | P20: =SUM(D20:O20) | Q20: A | R20: Uniform until the Rwandan harvest calendar is sourced
A21: MAC_SEASON | B21: Macadamia (nut in shell) | C21: share of year | D21: 0.083333 | E21: 0.083333 | F21: 0.083333 | G21: 0.083333 | H21: 0.083333 | I21: 0.083333 | J21: 0.083333 | K21: 0.083333 | L21: 0.083333 | M21: 0.083333 | N21: 0.083333 | O21: 0.083337 | P21: =SUM(D21:O21) | Q21: A | R21: Uniform until the Rwandan harvest calendar is sourced
A24: ID | B24: Series | C24: Unit | D24: Jan | E24: Feb | F24: Mar | G24: Apr | H24: May | I24: Jun | J24: Jul | K24: Aug | L24: Sep | M24: Oct | N24: Nov | O24: Dec | P24: Average (must be 1) | Q24: Label | R24: Note
A25: PGROWTH | B25: Pasture growth factor | C25: x average | D25: 0.9 | E25: 0.8 | F25: 1.3 | G25: 1.5 | H25: 1.4 | I25: 0.6 | J25: 0.4 | K25: 0.4 | L25: 0.8 | M25: 1.2 | N25: 1.4 | O25: 1.3 | P25: =AVERAGE(D25:O25) | Q25: A | R25: Shape follows the bimodal rains; calibrate to zone rainfall

Sheet Sensitivity
A1: Sensitivity
A2: Multipliers that flex the drivers that matter most. Leave at 1 (delay 0) for the plain scenario.
A4: Key | B4: Driver | C4: Setting | D4: How it is applied
A5: S_PRICE_FRUIT | B5: Fruit prices | C5: 1 | D5: Multiplies every fruit farm-gate price
A6: S_PRICE_LIVE | B6: Livestock prices | C6: 1 | D6: Multiplies the live-weight price of goats and sheep
A7: S_YIELD | B7: Fruit yields | C7: 1 | D7: Multiplies every yield curve
A8: S_MORT | B8: Livestock mortality | C8: 1 | D8: Multiplies young and adult mortality
A9: S_FEED | B9: Purchased feed cost | C9: 1 | D9: Multiplies the purchased-feed price
A10: S_LABOR | B10: Labour cost | C10: 1 | D10: Multiplies permanent and casual wages
A11: S_CAPEX | B11: Capital costs | C11: 1 | D11: Multiplies every capital item, seedling and animal purchase
A12: S_TRANS | B12: Transport cost | C12: 1 | D12: Multiplies transport per kg and per head
A13: S_DELAY | B13: Delay to tree maturity | C13: 0 | D13: Years added before perennial trees start their yield curve
B16: Results log (Stage 3): set one driver at a time to 0.8 and 1.2, record the outputs, reset to 1.
B17: Driver | C17: Setting | D17: NPV (RWF) | E17: Funding gap (RWF) | F17: Payback year | G17: Date / note

Sheet Land
A1: Land
A2: Areas by zone and crop for the selected model.
A3: Key | B3: Item | C3: Value | D3: Unit
A4: L_AREA | B4: Total area | C4: =Control!$C$7 | D4: ha
A5: L_PERIM | B5: Perimeter of a square of that area | C5: =4*SQRT(C4*10000) | D5: m
A6: L_BOUND | B6: Boundary length with shape factor | C6: =C5*Assumptions!$H$184 | D6: m
A7: L_Z01 | B7: Z0+Z1 base, store, nursery | C7: =C4*Models!$H$6 | D7: ha
A8: L_Z2 | B8: Z2 orchard | C8: =C4*Models!$H$7 | D8: ha
A9: L_Z3 | B9: Z3 paddocks and fodder bank | C9: =C4*Models!$H$8 | D9: ha
A10: L_Z4 | B10: Z4 boundary and shelter trees | C10: =C4*Models!$H$9 | D10: ha
A11: L_Z5 | B11: Z5 buffer and conservation | C11: =C4*Models!$H$10 | D11: ha
A12: L_PADDOCK | B12: Paddocks (grazed) | C12: =C9*(1-Models!$H$11) | D12: ha
A13: L_FODDER | B13: Fodder bank (cut-and-carry) | C13: =C9*Models!$H$11 | D13: ha
B15: Orchard by crop
A16: L_AVO | B16: Avocado (grafted) | C16: =Land!$C$8*Models!$H$13 | D16: ha
A17: L_MAN | B17: Mango (grafted) | C17: =Land!$C$8*Models!$H$14 | D17: ha
A18: L_PAS | B18: Passion fruit | C18: =Land!$C$8*Models!$H$15 | D18: ha
A19: L_PAP | B19: Papaya | C19: =Land!$C$8*Models!$H$16 | D19: ha
A20: L_TTO | B20: Tree tomato | C20: =Land!$C$8*Models!$H$17 | D20: ha
A21: L_CIT | B21: Citrus | C21: =Land!$C$8*Models!$H$18 | D21: ha
A22: L_MAC | B22: Macadamia (nut in shell) | C22: =Land!$C$8*Models!$H$19 | D22: ha
B24: Checks
B25: Land shares sum to 100% | C25: =Models!$H$6+Models!$H$7+Models!$H$8+Models!$H$9+Models!$H$10
B26: Orchard mix sums to 100% | C26: =Models!$H$13+Models!$H$14+Models!$H$15+Models!$H$16+Models!$H$17+Models!$H$18+Models!$H$19

Sheet Trees
A1: Trees
A2: Annual orchard and boundary-tree engine for the selected model and scenario.
B3: Farm year | D3: 1 | E3: 2 | F3: 3 | G3: 4 | H3: 5 | I3: 6 | J3: 7 | K3: 8 | L3: 9 | M3: 10
B5: Avocado (grafted)
A6: AVO_AREA | B6: Area | C6: =Land!$C$16
A7: AVO_PLANTS | B7: Plants planted | C7: =ROUND(C6*Assumptions!$H$121,0)
A8: AVO_STAND | B8: Final stand | C8: =C7*Assumptions!$H$122
A9: AVO_EST | B9: Establishment cost | C9: =C7*(Assumptions!$H$123+Assumptions!$H$124)*Sensitivity!$C$11
A10: AVO_GAP | B10: Gap-filling cost (year 2) | C10: =C7*(1-Assumptions!$H$122)*Assumptions!$H$123*Sensitivity!$C$11
A11: AVO_AGE | B11: Age in production cycle | C11: years | D11: =IF(Assumptions!$H$128=0,D$3-Sensitivity!$C$13,MOD(D$3-1,MAX(1,Assumptions!$H$128))+1) | E11: =IF(Assumptions!$H$128=0,E$3-Sensitivity!$C$13,MOD(E$3-1,MAX(1,Assumptions!$H$128))+1) | F11: =IF(Assumptions!$H$128=0,F$3-Sensitivity!$C$13,MOD(F$3-1,MAX(1,Assumptions!$H$128))+1) | G11: =IF(Assumptions!$H$128=0,G$3-Sensitivity!$C$13,MOD(G$3-1,MAX(1,Assumptions!$H$128))+1) | H11: =IF(Assumptions!$H$128=0,H$3-Sensitivity!$C$13,MOD(H$3-1,MAX(1,Assumptions!$H$128))+1) | I11: =IF(Assumptions!$H$128=0,I$3-Sensitivity!$C$13,MOD(I$3-1,MAX(1,Assumptions!$H$128))+1) | J11: =IF(Assumptions!$H$128=0,J$3-Sensitivity!$C$13,MOD(J$3-1,MAX(1,Assumptions!$H$128))+1) | K11: =IF(Assumptions!$H$128=0,K$3-Sensitivity!$C$13,MOD(K$3-1,MAX(1,Assumptions!$H$128))+1) | ... M11: =IF(Assumptions!$H$128=0,M$3-Sensitivity!$C$13,MOD(M$3-1,MAX(1,Assumptions!$H$128))+1)
A12: AVO_YLD | B12: Yield per plant | C12: kg | D12: =IF(D11>=1,INDEX(Curves!$D$5:$M$5,1,MIN(10,MAX(1,D11))),0)*Assumptions!$H$125*Sensitivity!$C$7 | E12: =IF(E11>=1,INDEX(Curves!$D$5:$M$5,1,MIN(10,MAX(1,E11))),0)*Assumptions!$H$125*Sensitivity!$C$7 | F12: =IF(F11>=1,INDEX(Curves!$D$5:$M$5,1,MIN(10,MAX(1,F11))),0)*Assumptions!$H$125*Sensitivity!$C$7 | G12: =IF(G11>=1,INDEX(Curves!$D$5:$M$5,1,MIN(10,MAX(1,G11))),0)*Assumptions!$H$125*Sensitivity!$C$7 | H12: =IF(H11>=1,INDEX(Curves!$D$5:$M$5,1,MIN(10,MAX(1,H11))),0)*Assumptions!$H$125*Sensitivity!$C$7 | I12: =IF(I11>=1,INDEX(Curves!$D$5:$M$5,1,MIN(10,MAX(1,I11))),0)*Assumptions!$H$125*Sensitivity!$C$7 | J12: =IF(J11>=1,INDEX(Curves!$D$5:$M$5,1,MIN(10,MAX(1,J11))),0)*Assumptions!$H$125*Sensitivity!$C$7 | K12: =IF(K11>=1,INDEX(Curves!$D$5:$M$5,1,MIN(10,MAX(1,K11))),0)*Assumptions!$H$125*Sensitivity!$C$7 | ... M12: =IF(M11>=1,INDEX(Curves!$D$5:$M$5,1,MIN(10,MAX(1,M11))),0)*Assumptions!$H$125*Sensitivity!$C$7
A13: AVO_PROD | B13: Marketable production | C13: kg | D13: =Trees!$C$8*D12*Assumptions!$H$126 | E13: =Trees!$C$8*E12*Assumptions!$H$126 | F13: =Trees!$C$8*F12*Assumptions!$H$126 | G13: =Trees!$C$8*G12*Assumptions!$H$126 | H13: =Trees!$C$8*H12*Assumptions!$H$126 | I13: =Trees!$C$8*I12*Assumptions!$H$126 | J13: =Trees!$C$8*J12*Assumptions!$H$126 | K13: =Trees!$C$8*K12*Assumptions!$H$126 | ... M13: =Trees!$C$8*M12*Assumptions!$H$126
A14: AVO_REV | B14: Sales | C14: RWF | D14: =D13*Assumptions!$H$127*Sensitivity!$C$5 | E14: =E13*Assumptions!$H$127*Sensitivity!$C$5 | F14: =F13*Assumptions!$H$127*Sensitivity!$C$5 | G14: =G13*Assumptions!$H$127*Sensitivity!$C$5 | H14: =H13*Assumptions!$H$127*Sensitivity!$C$5 | I14: =I13*Assumptions!$H$127*Sensitivity!$C$5 | J14: =J13*Assumptions!$H$127*Sensitivity!$C$5 | K14: =K13*Assumptions!$H$127*Sensitivity!$C$5 | ... M14: =M13*Assumptions!$H$127*Sensitivity!$C$5
A15: AVO_REPL | B15: Replanting (short-cycle crops) | C15: RWF | D15: =IF(AND(Assumptions!$H$128>0,D$3>1,MOD(D$3-1,MAX(1,Assumptions!$H$128))=0),Trees!$C$7*(Assumptions!$H$123+Assumptions!$H$124)*Sensitivity!$C$11,0) | E15: =IF(AND(Assumptions!$H$128>0,E$3>1,MOD(E$3-1,MAX(1,Assumptions!$H$128))=0),Trees!$C$7*(Assumptions!$H$123+Assumptions!$H$124)*Sensitivity!$C$11,0) | F15: =IF(AND(Assumptions!$H$128>0,F$3>1,MOD(F$3-1,MAX(1,Assumptions!$H$128))=0),Trees!$C$7*(Assumptions!$H$123+Assumptions!$H$124)*Sensitivity!$C$11,0) | G15: =IF(AND(Assumptions!$H$128>0,G$3>1,MOD(G$3-1,MAX(1,Assumptions!$H$128))=0),Trees!$C$7*(Assumptions!$H$123+Assumptions!$H$124)*Sensitivity!$C$11,0) | H15: =IF(AND(Assumptions!$H$128>0,H$3>1,MOD(H$3-1,MAX(1,Assumptions!$H$128))=0),Trees!$C$7*(Assumptions!$H$123+Assumptions!$H$124)*Sensitivity!$C$11,0) | I15: =IF(AND(Assumptions!$H$128>0,I$3>1,MOD(I$3-1,MAX(1,Assumptions!$H$128))=0),Trees!$C$7*(Assumptions!$H$123+Assumptions!$H$124)*Sensitivity!$C$11,0) | J15: =IF(AND(Assumptions!$H$128>0,J$3>1,MOD(J$3-1,MAX(1,Assumptions!$H$128))=0),Trees!$C$7*(Assumptions!$H$123+Assumptions!$H$124)*Sensitivity!$C$11,0) | K15: =IF(AND(Assumptions!$H$128>0,K$3>1,MOD(K$3-1,MAX(1,Assumptions!$H$128))=0),Trees!$C$7*(Assumptions!$H$123+Assumptions!$H$124)*Sensitivity!$C$11,0) | ... M15: =IF(AND(Assumptions!$H$128>0,M$3>1,MOD(M$3-1,MAX(1,Assumptions!$H$128))=0),Trees!$C$7*(Assumptions!$H$123+Assumptions!$H$124)*Sensitivity!$C$11,0)
B17: Mango (grafted)
A18: MAN_AREA | B18: Area | C18: =Land!$C$17
A19: MAN_PLANTS | B19: Plants planted | C19: =ROUND(C18*Assumptions!$H$130,0)
A20: MAN_STAND | B20: Final stand | C20: =C19*Assumptions!$H$131
A21: MAN_EST | B21: Establishment cost | C21: =C19*(Assumptions!$H$132+Assumptions!$H$133)*Sensitivity!$C$11
A22: MAN_GAP | B22: Gap-filling cost (year 2) | C22: =C19*(1-Assumptions!$H$131)*Assumptions!$H$132*Sensitivity!$C$11
A23: MAN_AGE | B23: Age in production cycle | C23: years | D23: =IF(Assumptions!$H$137=0,D$3-Sensitivity!$C$13,MOD(D$3-1,MAX(1,Assumptions!$H$137))+1) | E23: =IF(Assumptions!$H$137=0,E$3-Sensitivity!$C$13,MOD(E$3-1,MAX(1,Assumptions!$H$137))+1) | F23: =IF(Assumptions!$H$137=0,F$3-Sensitivity!$C$13,MOD(F$3-1,MAX(1,Assumptions!$H$137))+1) | G23: =IF(Assumptions!$H$137=0,G$3-Sensitivity!$C$13,MOD(G$3-1,MAX(1,Assumptions!$H$137))+1) | H23: =IF(Assumptions!$H$137=0,H$3-Sensitivity!$C$13,MOD(H$3-1,MAX(1,Assumptions!$H$137))+1) | I23: =IF(Assumptions!$H$137=0,I$3-Sensitivity!$C$13,MOD(I$3-1,MAX(1,Assumptions!$H$137))+1) | J23: =IF(Assumptions!$H$137=0,J$3-Sensitivity!$C$13,MOD(J$3-1,MAX(1,Assumptions!$H$137))+1) | K23: =IF(Assumptions!$H$137=0,K$3-Sensitivity!$C$13,MOD(K$3-1,MAX(1,Assumptions!$H$137))+1) | ... M23: =IF(Assumptions!$H$137=0,M$3-Sensitivity!$C$13,MOD(M$3-1,MAX(1,Assumptions!$H$137))+1)
A24: MAN_YLD | B24: Yield per plant | C24: kg | D24: =IF(D23>=1,INDEX(Curves!$D$6:$M$6,1,MIN(10,MAX(1,D23))),0)*Assumptions!$H$134*Sensitivity!$C$7 | E24: =IF(E23>=1,INDEX(Curves!$D$6:$M$6,1,MIN(10,MAX(1,E23))),0)*Assumptions!$H$134*Sensitivity!$C$7 | F24: =IF(F23>=1,INDEX(Curves!$D$6:$M$6,1,MIN(10,MAX(1,F23))),0)*Assumptions!$H$134*Sensitivity!$C$7 | G24: =IF(G23>=1,INDEX(Curves!$D$6:$M$6,1,MIN(10,MAX(1,G23))),0)*Assumptions!$H$134*Sensitivity!$C$7 | H24: =IF(H23>=1,INDEX(Curves!$D$6:$M$6,1,MIN(10,MAX(1,H23))),0)*Assumptions!$H$134*Sensitivity!$C$7 | I24: =IF(I23>=1,INDEX(Curves!$D$6:$M$6,1,MIN(10,MAX(1,I23))),0)*Assumptions!$H$134*Sensitivity!$C$7 | J24: =IF(J23>=1,INDEX(Curves!$D$6:$M$6,1,MIN(10,MAX(1,J23))),0)*Assumptions!$H$134*Sensitivity!$C$7 | K24: =IF(K23>=1,INDEX(Curves!$D$6:$M$6,1,MIN(10,MAX(1,K23))),0)*Assumptions!$H$134*Sensitivity!$C$7 | ... M24: =IF(M23>=1,INDEX(Curves!$D$6:$M$6,1,MIN(10,MAX(1,M23))),0)*Assumptions!$H$134*Sensitivity!$C$7
A25: MAN_PROD | B25: Marketable production | C25: kg | D25: =Trees!$C$20*D24*Assumptions!$H$135 | E25: =Trees!$C$20*E24*Assumptions!$H$135 | F25: =Trees!$C$20*F24*Assumptions!$H$135 | G25: =Trees!$C$20*G24*Assumptions!$H$135 | H25: =Trees!$C$20*H24*Assumptions!$H$135 | I25: =Trees!$C$20*I24*Assumptions!$H$135 | J25: =Trees!$C$20*J24*Assumptions!$H$135 | K25: =Trees!$C$20*K24*Assumptions!$H$135 | ... M25: =Trees!$C$20*M24*Assumptions!$H$135
A26: MAN_REV | B26: Sales | C26: RWF | D26: =D25*Assumptions!$H$136*Sensitivity!$C$5 | E26: =E25*Assumptions!$H$136*Sensitivity!$C$5 | F26: =F25*Assumptions!$H$136*Sensitivity!$C$5 | G26: =G25*Assumptions!$H$136*Sensitivity!$C$5 | H26: =H25*Assumptions!$H$136*Sensitivity!$C$5 | I26: =I25*Assumptions!$H$136*Sensitivity!$C$5 | J26: =J25*Assumptions!$H$136*Sensitivity!$C$5 | K26: =K25*Assumptions!$H$136*Sensitivity!$C$5 | ... M26: =M25*Assumptions!$H$136*Sensitivity!$C$5
A27: MAN_REPL | B27: Replanting (short-cycle crops) | C27: RWF | D27: =IF(AND(Assumptions!$H$137>0,D$3>1,MOD(D$3-1,MAX(1,Assumptions!$H$137))=0),Trees!$C$19*(Assumptions!$H$132+Assumptions!$H$133)*Sensitivity!$C$11,0) | E27: =IF(AND(Assumptions!$H$137>0,E$3>1,MOD(E$3-1,MAX(1,Assumptions!$H$137))=0),Trees!$C$19*(Assumptions!$H$132+Assumptions!$H$133)*Sensitivity!$C$11,0) | F27: =IF(AND(Assumptions!$H$137>0,F$3>1,MOD(F$3-1,MAX(1,Assumptions!$H$137))=0),Trees!$C$19*(Assumptions!$H$132+Assumptions!$H$133)*Sensitivity!$C$11,0) | G27: =IF(AND(Assumptions!$H$137>0,G$3>1,MOD(G$3-1,MAX(1,Assumptions!$H$137))=0),Trees!$C$19*(Assumptions!$H$132+Assumptions!$H$133)*Sensitivity!$C$11,0) | H27: =IF(AND(Assumptions!$H$137>0,H$3>1,MOD(H$3-1,MAX(1,Assumptions!$H$137))=0),Trees!$C$19*(Assumptions!$H$132+Assumptions!$H$133)*Sensitivity!$C$11,0) | I27: =IF(AND(Assumptions!$H$137>0,I$3>1,MOD(I$3-1,MAX(1,Assumptions!$H$137))=0),Trees!$C$19*(Assumptions!$H$132+Assumptions!$H$133)*Sensitivity!$C$11,0) | J27: =IF(AND(Assumptions!$H$137>0,J$3>1,MOD(J$3-1,MAX(1,Assumptions!$H$137))=0),Trees!$C$19*(Assumptions!$H$132+Assumptions!$H$133)*Sensitivity!$C$11,0) | K27: =IF(AND(Assumptions!$H$137>0,K$3>1,MOD(K$3-1,MAX(1,Assumptions!$H$137))=0),Trees!$C$19*(Assumptions!$H$132+Assumptions!$H$133)*Sensitivity!$C$11,0) | ... M27: =IF(AND(Assumptions!$H$137>0,M$3>1,MOD(M$3-1,MAX(1,Assumptions!$H$137))=0),Trees!$C$19*(Assumptions!$H$132+Assumptions!$H$133)*Sensitivity!$C$11,0)
B29: Passion fruit
A30: PAS_AREA | B30: Area | C30: =Land!$C$18
A31: PAS_PLANTS | B31: Plants planted | C31: =ROUND(C30*Assumptions!$H$139,0)
A32: PAS_STAND | B32: Final stand | C32: =C31*Assumptions!$H$140
A33: PAS_EST | B33: Establishment cost | C33: =C31*(Assumptions!$H$141+Assumptions!$H$142)*Sensitivity!$C$11
A34: PAS_GAP | B34: Gap-filling cost (year 2) | C34: =C31*(1-Assumptions!$H$140)*Assumptions!$H$141*Sensitivity!$C$11
A35: PAS_AGE | B35: Age in production cycle | C35: years | D35: =IF(Assumptions!$H$146=0,D$3-Sensitivity!$C$13,MOD(D$3-1,MAX(1,Assumptions!$H$146))+1) | E35: =IF(Assumptions!$H$146=0,E$3-Sensitivity!$C$13,MOD(E$3-1,MAX(1,Assumptions!$H$146))+1) | F35: =IF(Assumptions!$H$146=0,F$3-Sensitivity!$C$13,MOD(F$3-1,MAX(1,Assumptions!$H$146))+1) | G35: =IF(Assumptions!$H$146=0,G$3-Sensitivity!$C$13,MOD(G$3-1,MAX(1,Assumptions!$H$146))+1) | H35: =IF(Assumptions!$H$146=0,H$3-Sensitivity!$C$13,MOD(H$3-1,MAX(1,Assumptions!$H$146))+1) | I35: =IF(Assumptions!$H$146=0,I$3-Sensitivity!$C$13,MOD(I$3-1,MAX(1,Assumptions!$H$146))+1) | J35: =IF(Assumptions!$H$146=0,J$3-Sensitivity!$C$13,MOD(J$3-1,MAX(1,Assumptions!$H$146))+1) | K35: =IF(Assumptions!$H$146=0,K$3-Sensitivity!$C$13,MOD(K$3-1,MAX(1,Assumptions!$H$146))+1) | ... M35: =IF(Assumptions!$H$146=0,M$3-Sensitivity!$C$13,MOD(M$3-1,MAX(1,Assumptions!$H$146))+1)
A36: PAS_YLD | B36: Yield per plant | C36: kg | D36: =IF(D35>=1,INDEX(Curves!$D$7:$M$7,1,MIN(10,MAX(1,D35))),0)*Assumptions!$H$143*Sensitivity!$C$7 | E36: =IF(E35>=1,INDEX(Curves!$D$7:$M$7,1,MIN(10,MAX(1,E35))),0)*Assumptions!$H$143*Sensitivity!$C$7 | F36: =IF(F35>=1,INDEX(Curves!$D$7:$M$7,1,MIN(10,MAX(1,F35))),0)*Assumptions!$H$143*Sensitivity!$C$7 | G36: =IF(G35>=1,INDEX(Curves!$D$7:$M$7,1,MIN(10,MAX(1,G35))),0)*Assumptions!$H$143*Sensitivity!$C$7 | H36: =IF(H35>=1,INDEX(Curves!$D$7:$M$7,1,MIN(10,MAX(1,H35))),0)*Assumptions!$H$143*Sensitivity!$C$7 | I36: =IF(I35>=1,INDEX(Curves!$D$7:$M$7,1,MIN(10,MAX(1,I35))),0)*Assumptions!$H$143*Sensitivity!$C$7 | J36: =IF(J35>=1,INDEX(Curves!$D$7:$M$7,1,MIN(10,MAX(1,J35))),0)*Assumptions!$H$143*Sensitivity!$C$7 | K36: =IF(K35>=1,INDEX(Curves!$D$7:$M$7,1,MIN(10,MAX(1,K35))),0)*Assumptions!$H$143*Sensitivity!$C$7 | ... M36: =IF(M35>=1,INDEX(Curves!$D$7:$M$7,1,MIN(10,MAX(1,M35))),0)*Assumptions!$H$143*Sensitivity!$C$7
A37: PAS_PROD | B37: Marketable production | C37: kg | D37: =Trees!$C$32*D36*Assumptions!$H$144 | E37: =Trees!$C$32*E36*Assumptions!$H$144 | F37: =Trees!$C$32*F36*Assumptions!$H$144 | G37: =Trees!$C$32*G36*Assumptions!$H$144 | H37: =Trees!$C$32*H36*Assumptions!$H$144 | I37: =Trees!$C$32*I36*Assumptions!$H$144 | J37: =Trees!$C$32*J36*Assumptions!$H$144 | K37: =Trees!$C$32*K36*Assumptions!$H$144 | ... M37: =Trees!$C$32*M36*Assumptions!$H$144
A38: PAS_REV | B38: Sales | C38: RWF | D38: =D37*Assumptions!$H$145*Sensitivity!$C$5 | E38: =E37*Assumptions!$H$145*Sensitivity!$C$5 | F38: =F37*Assumptions!$H$145*Sensitivity!$C$5 | G38: =G37*Assumptions!$H$145*Sensitivity!$C$5 | H38: =H37*Assumptions!$H$145*Sensitivity!$C$5 | I38: =I37*Assumptions!$H$145*Sensitivity!$C$5 | J38: =J37*Assumptions!$H$145*Sensitivity!$C$5 | K38: =K37*Assumptions!$H$145*Sensitivity!$C$5 | ... M38: =M37*Assumptions!$H$145*Sensitivity!$C$5
A39: PAS_REPL | B39: Replanting (short-cycle crops) | C39: RWF | D39: =IF(AND(Assumptions!$H$146>0,D$3>1,MOD(D$3-1,MAX(1,Assumptions!$H$146))=0),Trees!$C$31*(Assumptions!$H$141+Assumptions!$H$142)*Sensitivity!$C$11,0) | E39: =IF(AND(Assumptions!$H$146>0,E$3>1,MOD(E$3-1,MAX(1,Assumptions!$H$146))=0),Trees!$C$31*(Assumptions!$H$141+Assumptions!$H$142)*Sensitivity!$C$11,0) | F39: =IF(AND(Assumptions!$H$146>0,F$3>1,MOD(F$3-1,MAX(1,Assumptions!$H$146))=0),Trees!$C$31*(Assumptions!$H$141+Assumptions!$H$142)*Sensitivity!$C$11,0) | G39: =IF(AND(Assumptions!$H$146>0,G$3>1,MOD(G$3-1,MAX(1,Assumptions!$H$146))=0),Trees!$C$31*(Assumptions!$H$141+Assumptions!$H$142)*Sensitivity!$C$11,0) | H39: =IF(AND(Assumptions!$H$146>0,H$3>1,MOD(H$3-1,MAX(1,Assumptions!$H$146))=0),Trees!$C$31*(Assumptions!$H$141+Assumptions!$H$142)*Sensitivity!$C$11,0) | I39: =IF(AND(Assumptions!$H$146>0,I$3>1,MOD(I$3-1,MAX(1,Assumptions!$H$146))=0),Trees!$C$31*(Assumptions!$H$141+Assumptions!$H$142)*Sensitivity!$C$11,0) | J39: =IF(AND(Assumptions!$H$146>0,J$3>1,MOD(J$3-1,MAX(1,Assumptions!$H$146))=0),Trees!$C$31*(Assumptions!$H$141+Assumptions!$H$142)*Sensitivity!$C$11,0) | K39: =IF(AND(Assumptions!$H$146>0,K$3>1,MOD(K$3-1,MAX(1,Assumptions!$H$146))=0),Trees!$C$31*(Assumptions!$H$141+Assumptions!$H$142)*Sensitivity!$C$11,0) | ... M39: =IF(AND(Assumptions!$H$146>0,M$3>1,MOD(M$3-1,MAX(1,Assumptions!$H$146))=0),Trees!$C$31*(Assumptions!$H$141+Assumptions!$H$142)*Sensitivity!$C$11,0)
B41: Papaya
A42: PAP_AREA | B42: Area | C42: =Land!$C$19
A43: PAP_PLANTS | B43: Plants planted | C43: =ROUND(C42*Assumptions!$H$148,0)
A44: PAP_STAND | B44: Final stand | C44: =C43*Assumptions!$H$149
...

Sheet Livestock
A1: Livestock
A2: Monthly herd engine. Young are sold at 9 months; females give first birth 6 months after joining.
B3: Month | D3: 1 | E3: 2 | F3: 3 | G3: 4 | H3: 5 | I3: 6 | J3: 7 | K3: 8 | L3: 9 | M3: 10 | N3: 11 | O3: 12 | P3: 13 | Q3: 14 | R3: 15 | S3: 16 | T3: 17 | U3: 18 | V3: 19 | W3: 20 | X3: 21 | Y3: 22 | Z3: 23 | AA3: 24 | AB3: 25 | AC3: 26 | AD3: 27 | AE3: 28 | AF3: 29 | AG3: 30 | AH3: 31 | AI3: 32 | AJ3: 33 | AK3: 34 | AL3: 35 | AM3: 36 | AN3: 37 | AO3: 38 | AP3: 39 | AQ3: 40 | AR3: 41 | AS3: 42 | AT3: 43 | AU3: 44 | AV3: 45 | AW3: 46 | AX3: 47 | AY3: 48 | AZ3: 49 | BA3: 50 | BB3: 51 | BC3: 52 | BD3: 53 | BE3: 54 | BF3: 55 | BG3: 56 | BH3: 57 | BI3: 58 | BJ3: 59 | BK3: 60 | BL3: 61 | BM3: 62 | BN3: 63 | BO3: 64 | BP3: 65 | BQ3: 66 | BR3: 67 | BS3: 68 | BT3: 69 | BU3: 70 | BV3: 71 | BW3: 72 | BX3: 73 | BY3: 74 | BZ3: 75 | CA3: 76 | CB3: 77 | CC3: 78 | CD3: 79 | CE3: 80 | CF3: 81 | CG3: 82 | CH3: 83 | CI3: 84 | CJ3: 85 | CK3: 86 | CL3: 87 | CM3: 88 | CN3: 89 | CO3: 90 | CP3: 91 | CQ3: 92 | CR3: 93 | CS3: 94 | CT3: 95 | CU3: 96 | CV3: 97 | CW3: 98 | CX3: 99 | CY3: 100 | CZ3: 101 | DA3: 102 | DB3: 103 | DC3: 104 | DD3: 105 | DE3: 106 | DF3: 107 | DG3: 108 | DH3: 109 | DI3: 110 | DJ3: 111 | DK3: 112 | DL3: 113 | DM3: 114 | DN3: 115 | DO3: 116 | DP3: 117 | DQ3: 118 | DR3: 119 | DS3: 120
B4: Farm year | D4: =INT((D$3-1)/12)+1 | E4: =INT((E$3-1)/12)+1 | F4: =INT((F$3-1)/12)+1 | G4: =INT((G$3-1)/12)+1 | H4: =INT((H$3-1)/12)+1 | I4: =INT((I$3-1)/12)+1 | J4: =INT((J$3-1)/12)+1 | K4: =INT((K$3-1)/12)+1 | ... DS4: =INT((DS$3-1)/12)+1
B5: Calendar month | D5: =MOD(Control!$C$10+D$3-2,12)+1 | E5: =MOD(Control!$C$10+E$3-2,12)+1 | F5: =MOD(Control!$C$10+F$3-2,12)+1 | G5: =MOD(Control!$C$10+G$3-2,12)+1 | H5: =MOD(Control!$C$10+H$3-2,12)+1 | I5: =MOD(Control!$C$10+I$3-2,12)+1 | J5: =MOD(Control!$C$10+J$3-2,12)+1 | K5: =MOD(Control!$C$10+K$3-2,12)+1 | ... DS5: =MOD(Control!$C$10+DS$3-2,12)+1
B6: Month starting | D6: =DATE(Control!$C$9+INT((Control!$C$10+D$3-2)/12),D$5,1) | E6: =DATE(Control!$C$9+INT((Control!$C$10+E$3-2)/12),E$5,1) | F6: =DATE(Control!$C$9+INT((Control!$C$10+F$3-2)/12),F$5,1) | G6: =DATE(Control!$C$9+INT((Control!$C$10+G$3-2)/12),G$5,1) | H6: =DATE(Control!$C$9+INT((Control!$C$10+H$3-2)/12),H$5,1) | I6: =DATE(Control!$C$9+INT((Control!$C$10+I$3-2)/12),I$5,1) | J6: =DATE(Control!$C$9+INT((Control!$C$10+J$3-2)/12),J$5,1) | K6: =DATE(Control!$C$9+INT((Control!$C$10+K$3-2)/12),K$5,1) | ... DS6: =DATE(Control!$C$9+INT((Control!$C$10+DS$3-2)/12),DS$5,1)
B8: Goats
A9: GT_FBUY | B9: Breeding females bought | C9: head | D9: =IF(D$3=Models!$H$21,Models!$H$22,0)+IF(D$3=Models!$H$24,Models!$H$25,0) | E9: =IF(E$3=Models!$H$21,Models!$H$22,0)+IF(E$3=Models!$H$24,Models!$H$25,0) | F9: =IF(F$3=Models!$H$21,Models!$H$22,0)+IF(F$3=Models!$H$24,Models!$H$25,0) | G9: =IF(G$3=Models!$H$21,Models!$H$22,0)+IF(G$3=Models!$H$24,Models!$H$25,0) | H9: =IF(H$3=Models!$H$21,Models!$H$22,0)+IF(H$3=Models!$H$24,Models!$H$25,0) | I9: =IF(I$3=Models!$H$21,Models!$H$22,0)+IF(I$3=Models!$H$24,Models!$H$25,0) | J9: =IF(J$3=Models!$H$21,Models!$H$22,0)+IF(J$3=Models!$H$24,Models!$H$25,0) | K9: =IF(K$3=Models!$H$21,Models!$H$22,0)+IF(K$3=Models!$H$24,Models!$H$25,0) | ... DS9: =IF(DS$3=Models!$H$21,Models!$H$22,0)+IF(DS$3=Models!$H$24,Models!$H$25,0)
A10: GT_MBUYT | B10: Breeding males bought in tranches | C10: head | D10: =IF(D$3=Models!$H$21,Models!$H$23,0)+IF(D$3=Models!$H$24,Models!$H$26,0) | E10: =IF(E$3=Models!$H$21,Models!$H$23,0)+IF(E$3=Models!$H$24,Models!$H$26,0) | F10: =IF(F$3=Models!$H$21,Models!$H$23,0)+IF(F$3=Models!$H$24,Models!$H$26,0) | G10: =IF(G$3=Models!$H$21,Models!$H$23,0)+IF(G$3=Models!$H$24,Models!$H$26,0) | H10: =IF(H$3=Models!$H$21,Models!$H$23,0)+IF(H$3=Models!$H$24,Models!$H$26,0) | I10: =IF(I$3=Models!$H$21,Models!$H$23,0)+IF(I$3=Models!$H$24,Models!$H$26,0) | J10: =IF(J$3=Models!$H$21,Models!$H$23,0)+IF(J$3=Models!$H$24,Models!$H$26,0) | K10: =IF(K$3=Models!$H$21,Models!$H$23,0)+IF(K$3=Models!$H$24,Models!$H$26,0) | ... DS10: =IF(DS$3=Models!$H$21,Models!$H$23,0)+IF(DS$3=Models!$H$24,Models!$H$26,0)
A11: GT_FOPEN | B11: Breeding females, opening | C11: head | D11: =0 | E11: =D18 | F11: =E18 | G11: =F18 | H11: =G18 | I11: =H18 | J11: =I18 | K11: =J18 | L11: =K18 | ... DS11: =DR18
A12: GT_FDEATH | B12: Female deaths | C12: head | D12: =D11*MIN(1,Assumptions!$H$73*Sensitivity!$C$8)/12 | E12: =E11*MIN(1,Assumptions!$H$73*Sensitivity!$C$8)/12 | F12: =F11*MIN(1,Assumptions!$H$73*Sensitivity!$C$8)/12 | G12: =G11*MIN(1,Assumptions!$H$73*Sensitivity!$C$8)/12 | H12: =H11*MIN(1,Assumptions!$H$73*Sensitivity!$C$8)/12 | I12: =I11*MIN(1,Assumptions!$H$73*Sensitivity!$C$8)/12 | J12: =J11*MIN(1,Assumptions!$H$73*Sensitivity!$C$8)/12 | K12: =K11*MIN(1,Assumptions!$H$73*Sensitivity!$C$8)/12 | ... DS12: =DS11*MIN(1,Assumptions!$H$73*Sensitivity!$C$8)/12
A13: GT_FCULL | B13: Females culled (sold) | C13: head | D13: =D11*Assumptions!$H$77/12 | E13: =E11*Assumptions!$H$77/12 | F13: =F11*Assumptions!$H$77/12 | G13: =G11*Assumptions!$H$77/12 | H13: =H11*Assumptions!$H$77/12 | I13: =I11*Assumptions!$H$77/12 | J13: =J11*Assumptions!$H$77/12 | K13: =K11*Assumptions!$H$77/12 | ... DS13: =DS11*Assumptions!$H$77/12
A14: GT_BIRTHS | B14: Young born | C14: head | D14: =0 | E14: =0 | F14: =0 | G14: =0 | H14: =0 | I14: =0 | J14: =D18*Assumptions!$H$61/12*Assumptions!$H$65 | K14: =E18*Assumptions!$H$61/12*Assumptions!$H$65 | L14: =F18*Assumptions!$H$61/12*Assumptions!$H$65 | M14: =G18*Assumptions!$H$61/12*Assumptions!$H$65 | N14: =H18*Assumptions!$H$61/12*Assumptions!$H$65 | O14: =I18*Assumptions!$H$61/12*Assumptions!$H$65 | P14: =J18*Assumptions!$H$61/12*Assumptions!$H$65 | Q14: =K18*Assumptions!$H$61/12*Assumptions!$H$65 | ... DS14: =DM18*Assumptions!$H$61/12*Assumptions!$H$65
A15: GT_YSURV | B15: Young surviving to weaning | C15: head | D15: =D14*(1-MIN(1,Assumptions!$H$69*Sensitivity!$C$8)) | E15: =E14*(1-MIN(1,Assumptions!$H$69*Sensitivity!$C$8)) | F15: =F14*(1-MIN(1,Assumptions!$H$69*Sensitivity!$C$8)) | G15: =G14*(1-MIN(1,Assumptions!$H$69*Sensitivity!$C$8)) | H15: =H14*(1-MIN(1,Assumptions!$H$69*Sensitivity!$C$8)) | I15: =I14*(1-MIN(1,Assumptions!$H$69*Sensitivity!$C$8)) | J15: =J14*(1-MIN(1,Assumptions!$H$69*Sensitivity!$C$8)) | K15: =K14*(1-MIN(1,Assumptions!$H$69*Sensitivity!$C$8)) | ... DS15: =DS14*(1-MIN(1,Assumptions!$H$69*Sensitivity!$C$8))
A16: GT_YREACH | B16: Young reaching sale age (9 months) | C16: head | D16: =0 | E16: =0 | F16: =0 | G16: =0 | H16: =0 | I16: =0 | J16: =0 | K16: =0 | L16: =0 | M16: =D15 | N16: =E15 | O16: =F15 | P16: =G15 | Q16: =H15 | R16: =I15 | S16: =J15 | T16: =K15 | ... DS16: =DJ15
A17: GT_RETAINED | B17: Female young kept as replacements | C17: head | D17: =MIN(D16*Assumptions!$H$117*Models!$H$36,MAX(0,Models!$H$27-(D11-D12-D13+D9))) | E17: =MIN(E16*Assumptions!$H$117*Models!$H$36,MAX(0,Models!$H$27-(E11-E12-E13+E9))) | F17: =MIN(F16*Assumptions!$H$117*Models!$H$36,MAX(0,Models!$H$27-(F11-F12-F13+F9))) | G17: =MIN(G16*Assumptions!$H$117*Models!$H$36,MAX(0,Models!$H$27-(G11-G12-G13+G9))) | H17: =MIN(H16*Assumptions!$H$117*Models!$H$36,MAX(0,Models!$H$27-(H11-H12-H13+H9))) | I17: =MIN(I16*Assumptions!$H$117*Models!$H$36,MAX(0,Models!$H$27-(I11-I12-I13+I9))) | J17: =MIN(J16*Assumptions!$H$117*Models!$H$36,MAX(0,Models!$H$27-(J11-J12-J13+J9))) | K17: =MIN(K16*Assumptions!$H$117*Models!$H$36,MAX(0,Models!$H$27-(K11-K12-K13+K9))) | ... DS17: =MIN(DS16*Assumptions!$H$117*Models!$H$36,MAX(0,Models!$H$27-(DS11-DS12-DS13+DS9)))
A18: GT_FCLOSE | B18: Breeding females, closing | C18: head | D18: =D11-D12-D13+D9+D17 | E18: =E11-E12-E13+E9+E17 | F18: =F11-F12-F13+F9+F17 | G18: =G11-G12-G13+G9+G17 | H18: =H11-H12-H13+H9+H17 | I18: =I11-I12-I13+I9+I17 | J18: =J11-J12-J13+J9+J17 | K18: =K11-K12-K13+K9+K17 | ... DS18: =DS11-DS12-DS13+DS9+DS17
A19: GT_YSOLD | B19: Young sold | C19: head | D19: =D16-D17 | E19: =E16-E17 | F19: =F16-F17 | G19: =G16-G17 | H19: =H16-H17 | I19: =I16-I17 | J19: =J16-J17 | K19: =K16-K17 | ... DS19: =DS16-DS17
A20: GT_YHAND | B20: Young on hand | C20: head | D20: =0+D15-D16 | E20: =D20+E15-E16 | F20: =E20+F15-F16 | G20: =F20+G15-G16 | H20: =G20+H15-H16 | I20: =H20+I15-I16 | J20: =I20+J15-J16 | K20: =J20+K15-K16 | L20: =K20+L15-L16 | ... DS20: =DR20+DS15-DS16
A21: GT_MNEED | B21: Breeding males needed | C21: head | D21: =IF(D18>0,ROUNDUP(D18/Assumptions!$H$113,0),0) | E21: =IF(E18>0,ROUNDUP(E18/Assumptions!$H$113,0),0) | F21: =IF(F18>0,ROUNDUP(F18/Assumptions!$H$113,0),0) | G21: =IF(G18>0,ROUNDUP(G18/Assumptions!$H$113,0),0) | H21: =IF(H18>0,ROUNDUP(H18/Assumptions!$H$113,0),0) | I21: =IF(I18>0,ROUNDUP(I18/Assumptions!$H$113,0),0) | J21: =IF(J18>0,ROUNDUP(J18/Assumptions!$H$113,0),0) | K21: =IF(K18>0,ROUNDUP(K18/Assumptions!$H$113,0),0) | ... DS21: =IF(DS18>0,ROUNDUP(DS18/Assumptions!$H$113,0),0)
A22: GT_MALES | B22: Breeding males | C22: head | D22: =MAX(0+D10,D21) | E22: =MAX(D22+E10,E21) | F22: =MAX(E22+F10,F21) | G22: =MAX(F22+G10,G21) | H22: =MAX(G22+H10,H21) | I22: =MAX(H22+I10,I21) | J22: =MAX(I22+J10,J21) | K22: =MAX(J22+K10,K21) | L22: =MAX(K22+L10,L21) | ... DS22: =MAX(DR22+DS10,DS21)
A23: GT_MBUY | B23: Breeding males bought (all) | C23: head | D23: =D22-0 | E23: =E22-D22 | F23: =F22-E22 | G23: =G22-F22 | H23: =H22-G22 | I23: =I22-H22 | J23: =J22-I22 | K23: =K22-J22 | L23: =L22-K22 | ... DS23: =DS22-DR22
A24: GT_HEAD | B24: All animals | C24: head | D24: =D18+D22+D20 | E24: =E18+E22+E20 | F24: =F18+F22+F20 | G24: =G18+G22+G20 | H24: =H18+H22+H20 | I24: =I18+I22+I20 | J24: =J18+J22+J20 | K24: =K18+K22+K20 | ... DS24: =DS18+DS22+DS20
A25: GT_SOLDHD | B25: Animals sold | C25: head | D25: =D19+D13 | E25: =E19+E13 | F25: =F19+F13 | G25: =G19+G13 | H25: =H19+H13 | I25: =I19+I13 | J25: =J19+J13 | K25: =K19+K13 | ... DS25: =DS19+DS13
A26: GT_REV_Y | B26: Sales: young stock | C26: RWF | D26: =D19*Assumptions!$H$81*Assumptions!$H$89*Sensitivity!$C$6*(1+Models!$H$37*Assumptions!$H$101) | E26: =E19*Assumptions!$H$81*Assumptions!$H$89*Sensitivity!$C$6*(1+Models!$H$37*Assumptions!$H$101) | F26: =F19*Assumptions!$H$81*Assumptions!$H$89*Sensitivity!$C$6*(1+Models!$H$37*Assumptions!$H$101) | G26: =G19*Assumptions!$H$81*Assumptions!$H$89*Sensitivity!$C$6*(1+Models!$H$37*Assumptions!$H$101) | H26: =H19*Assumptions!$H$81*Assumptions!$H$89*Sensitivity!$C$6*(1+Models!$H$37*Assumptions!$H$101) | I26: =I19*Assumptions!$H$81*Assumptions!$H$89*Sensitivity!$C$6*(1+Models!$H$37*Assumptions!$H$101) | J26: =J19*Assumptions!$H$81*Assumptions!$H$89*Sensitivity!$C$6*(1+Models!$H$37*Assumptions!$H$101) | K26: =K19*Assumptions!$H$81*Assumptions!$H$89*Sensitivity!$C$6*(1+Models!$H$37*Assumptions!$H$101) | ... DS26: =DS19*Assumptions!$H$81*Assumptions!$H$89*Sensitivity!$C$6*(1+Models!$H$37*Assumptions!$H$101)
A27: GT_REV_C | B27: Sales: culled adults | C27: RWF | D27: =D13*Assumptions!$H$85*Assumptions!$H$89*Sensitivity!$C$6 | E27: =E13*Assumptions!$H$85*Assumptions!$H$89*Sensitivity!$C$6 | F27: =F13*Assumptions!$H$85*Assumptions!$H$89*Sensitivity!$C$6 | G27: =G13*Assumptions!$H$85*Assumptions!$H$89*Sensitivity!$C$6 | H27: =H13*Assumptions!$H$85*Assumptions!$H$89*Sensitivity!$C$6 | I27: =I13*Assumptions!$H$85*Assumptions!$H$89*Sensitivity!$C$6 | J27: =J13*Assumptions!$H$85*Assumptions!$H$89*Sensitivity!$C$6 | K27: =K13*Assumptions!$H$85*Assumptions!$H$89*Sensitivity!$C$6 | ... DS27: =DS13*Assumptions!$H$85*Assumptions!$H$89*Sensitivity!$C$6
A28: GT_BUYCOST | B28: Animal purchases | C28: RWF | D28: =(D9*Assumptions!$H$93+D23*Assumptions!$H$97)*Sensitivity!$C$11 | E28: =(E9*Assumptions!$H$93+E23*Assumptions!$H$97)*Sensitivity!$C$11 | F28: =(F9*Assumptions!$H$93+F23*Assumptions!$H$97)*Sensitivity!$C$11 | G28: =(G9*Assumptions!$H$93+G23*Assumptions!$H$97)*Sensitivity!$C$11 | H28: =(H9*Assumptions!$H$93+H23*Assumptions!$H$97)*Sensitivity!$C$11 | I28: =(I9*Assumptions!$H$93+I23*Assumptions!$H$97)*Sensitivity!$C$11 | J28: =(J9*Assumptions!$H$93+J23*Assumptions!$H$97)*Sensitivity!$C$11 | K28: =(K9*Assumptions!$H$93+K23*Assumptions!$H$97)*Sensitivity!$C$11 | ... DS28: =(DS9*Assumptions!$H$93+DS23*Assumptions!$H$97)*Sensitivity!$C$11
A29: GT_VALUE | B29: Breeding herd value (insurance basis) | C29: RWF | D29: =D18*Assumptions!$H$93+D22*Assumptions!$H$97 | E29: =E18*Assumptions!$H$93+E22*Assumptions!$H$97 | F29: =F18*Assumptions!$H$93+F22*Assumptions!$H$97 | G29: =G18*Assumptions!$H$93+G22*Assumptions!$H$97 | H29: =H18*Assumptions!$H$93+H22*Assumptions!$H$97 | I29: =I18*Assumptions!$H$93+I22*Assumptions!$H$97 | J29: =J18*Assumptions!$H$93+J22*Assumptions!$H$97 | K29: =K18*Assumptions!$H$93+K22*Assumptions!$H$97 | ... DS29: =DS18*Assumptions!$H$93+DS22*Assumptions!$H$97
A30: GT_DEMAND | B30: Feed demand | C30: kg DM | D30: =((D18+D22)*Assumptions!$H$105+D20*Assumptions!$H$109)*30.42 | E30: =((E18+E22)*Assumptions!$H$105+E20*Assumptions!$H$109)*30.42 | F30: =((F18+F22)*Assumptions!$H$105+F20*Assumptions!$H$109)*30.42 | G30: =((G18+G22)*Assumptions!$H$105+G20*Assumptions!$H$109)*30.42 | H30: =((H18+H22)*Assumptions!$H$105+H20*Assumptions!$H$109)*30.42 | I30: =((I18+I22)*Assumptions!$H$105+I20*Assumptions!$H$109)*30.42 | J30: =((J18+J22)*Assumptions!$H$105+J20*Assumptions!$H$109)*30.42 | K30: =((K18+K22)*Assumptions!$H$105+K20*Assumptions!$H$109)*30.42 | ... DS30: =((DS18+DS22)*Assumptions!$H$105+DS20*Assumptions!$H$109)*30.42
B32: Sheep
A33: SH_FBUY | B33: Breeding females bought | C33: head | D33: =IF(D$3=Models!$H$28,Models!$H$29,0)+IF(D$3=Models!$H$31,Models!$H$32,0) | E33: =IF(E$3=Models!$H$28,Models!$H$29,0)+IF(E$3=Models!$H$31,Models!$H$32,0) | F33: =IF(F$3=Models!$H$28,Models!$H$29,0)+IF(F$3=Models!$H$31,Models!$H$32,0) | G33: =IF(G$3=Models!$H$28,Models!$H$29,0)+IF(G$3=Models!$H$31,Models!$H$32,0) | H33: =IF(H$3=Models!$H$28,Models!$H$29,0)+IF(H$3=Models!$H$31,Models!$H$32,0) | I33: =IF(I$3=Models!$H$28,Models!$H$29,0)+IF(I$3=Models!$H$31,Models!$H$32,0) | J33: =IF(J$3=Models!$H$28,Models!$H$29,0)+IF(J$3=Models!$H$31,Models!$H$32,0) | K33: =IF(K$3=Models!$H$28,Models!$H$29,0)+IF(K$3=Models!$H$31,Models!$H$32,0) | ... DS33: =IF(DS$3=Models!$H$28,Models!$H$29,0)+IF(DS$3=Models!$H$31,Models!$H$32,0)
A34: SH_MBUYT | B34: Breeding males bought in tranches | C34: head | D34: =IF(D$3=Models!$H$28,Models!$H$30,0)+IF(D$3=Models!$H$31,Models!$H$33,0) | E34: =IF(E$3=Models!$H$28,Models!$H$30,0)+IF(E$3=Models!$H$31,Models!$H$33,0) | F34: =IF(F$3=Models!$H$28,Models!$H$30,0)+IF(F$3=Models!$H$31,Models!$H$33,0) | G34: =IF(G$3=Models!$H$28,Models!$H$30,0)+IF(G$3=Models!$H$31,Models!$H$33,0) | H34: =IF(H$3=Models!$H$28,Models!$H$30,0)+IF(H$3=Models!$H$31,Models!$H$33,0) | I34: =IF(I$3=Models!$H$28,Models!$H$30,0)+IF(I$3=Models!$H$31,Models!$H$33,0) | J34: =IF(J$3=Models!$H$28,Models!$H$30,0)+IF(J$3=Models!$H$31,Models!$H$33,0) | K34: =IF(K$3=Models!$H$28,Models!$H$30,0)+IF(K$3=Models!$H$31,Models!$H$33,0) | ... DS34: =IF(DS$3=Models!$H$28,Models!$H$30,0)+IF(DS$3=Models!$H$31,Models!$H$33,0)
A35: SH_FOPEN | B35: Breeding females, opening | C35: head | D35: =0 | E35: =D42 | F35: =E42 | G35: =F42 | H35: =G42 | I35: =H42 | J35: =I42 | K35: =J42 | L35: =K42 | ... DS35: =DR42
A36: SH_FDEATH | B36: Female deaths | C36: head | D36: =D35*MIN(1,Assumptions!$H$75*Sensitivity!$C$8)/12 | E36: =E35*MIN(1,Assumptions!$H$75*Sensitivity!$C$8)/12 | F36: =F35*MIN(1,Assumptions!$H$75*Sensitivity!$C$8)/12 | G36: =G35*MIN(1,Assumptions!$H$75*Sensitivity!$C$8)/12 | H36: =H35*MIN(1,Assumptions!$H$75*Sensitivity!$C$8)/12 | I36: =I35*MIN(1,Assumptions!$H$75*Sensitivity!$C$8)/12 | J36: =J35*MIN(1,Assumptions!$H$75*Sensitivity!$C$8)/12 | K36: =K35*MIN(1,Assumptions!$H$75*Sensitivity!$C$8)/12 | ... DS36: =DS35*MIN(1,Assumptions!$H$75*Sensitivity!$C$8)/12
A37: SH_FCULL | B37: Females culled (sold) | C37: head | D37: =D35*Assumptions!$H$79/12 | E37: =E35*Assumptions!$H$79/12 | F37: =F35*Assumptions!$H$79/12 | G37: =G35*Assumptions!$H$79/12 | H37: =H35*Assumptions!$H$79/12 | I37: =I35*Assumptions!$H$79/12 | J37: =J35*Assumptions!$H$79/12 | K37: =K35*Assumptions!$H$79/12 | ... DS37: =DS35*Assumptions!$H$79/12
A38: SH_BIRTHS | B38: Young born | C38: head | D38: =0 | E38: =0 | F38: =0 | G38: =0 | H38: =0 | I38: =0 | J38: =D42*Assumptions!$H$63/12*Assumptions!$H$67 | K38: =E42*Assumptions!$H$63/12*Assumptions!$H$67 | L38: =F42*Assumptions!$H$63/12*Assumptions!$H$67 | M38: =G42*Assumptions!$H$63/12*Assumptions!$H$67 | N38: =H42*Assumptions!$H$63/12*Assumptions!$H$67 | O38: =I42*Assumptions!$H$63/12*Assumptions!$H$67 | P38: =J42*Assumptions!$H$63/12*Assumptions!$H$67 | Q38: =K42*Assumptions!$H$63/12*Assumptions!$H$67 | ... DS38: =DM42*Assumptions!$H$63/12*Assumptions!$H$67
A39: SH_YSURV | B39: Young surviving to weaning | C39: head | D39: =D38*(1-MIN(1,Assumptions!$H$71*Sensitivity!$C$8)) | E39: =E38*(1-MIN(1,Assumptions!$H$71*Sensitivity!$C$8)) | F39: =F38*(1-MIN(1,Assumptions!$H$71*Sensitivity!$C$8)) | G39: =G38*(1-MIN(1,Assumptions!$H$71*Sensitivity!$C$8)) | H39: =H38*(1-MIN(1,Assumptions!$H$71*Sensitivity!$C$8)) | I39: =I38*(1-MIN(1,Assumptions!$H$71*Sensitivity!$C$8)) | J39: =J38*(1-MIN(1,Assumptions!$H$71*Sensitivity!$C$8)) | K39: =K38*(1-MIN(1,Assumptions!$H$71*Sensitivity!$C$8)) | ... DS39: =DS38*(1-MIN(1,Assumptions!$H$71*Sensitivity!$C$8))
A40: SH_YREACH | B40: Young reaching sale age (9 months) | C40: head | D40: =0 | E40: =0 | F40: =0 | G40: =0 | H40: =0 | I40: =0 | J40: =0 | K40: =0 | L40: =0 | M40: =D39 | N40: =E39 | O40: =F39 | P40: =G39 | Q40: =H39 | R40: =I39 | S40: =J39 | T40: =K39 | ... DS40: =DJ39
A41: SH_RETAINED | B41: Female young kept as replacements | C41: head | D41: =MIN(D40*Assumptions!$H$119*Models!$H$36,MAX(0,Models!$H$34-(D35-D36-D37+D33))) | E41: =MIN(E40*Assumptions!$H$119*Models!$H$36,MAX(0,Models!$H$34-(E35-E36-E37+E33))) | F41: =MIN(F40*Assumptions!$H$119*Models!$H$36,MAX(0,Models!$H$34-(F35-F36-F37+F33))) | G41: =MIN(G40*Assumptions!$H$119*Models!$H$36,MAX(0,Models!$H$34-(G35-G36-G37+G33))) | H41: =MIN(H40*Assumptions!$H$119*Models!$H$36,MAX(0,Models!$H$34-(H35-H36-H37+H33))) | I41: =MIN(I40*Assumptions!$H$119*Models!$H$36,MAX(0,Models!$H$34-(I35-I36-I37+I33))) | J41: =MIN(J40*Assumptions!$H$119*Models!$H$36,MAX(0,Models!$H$34-(J35-J36-J37+J33))) | K41: =MIN(K40*Assumptions!$H$119*Models!$H$36,MAX(0,Models!$H$34-(K35-K36-K37+K33))) | ... DS41: =MIN(DS40*Assumptions!$H$119*Models!$H$36,MAX(0,Models!$H$34-(DS35-DS36-DS37+DS33)))
A42: SH_FCLOSE | B42: Breeding females, closing | C42: head | D42: =D35-D36-D37+D33+D41 | E42: =E35-E36-E37+E33+E41 | F42: =F35-F36-F37+F33+F41 | G42: =G35-G36-G37+G33+G41 | H42: =H35-H36-H37+H33+H41 | I42: =I35-I36-I37+I33+I41 | J42: =J35-J36-J37+J33+J41 | K42: =K35-K36-K37+K33+K41 | ... DS42: =DS35-DS36-DS37+DS33+DS41
...

Sheet Feed
A1: Feed
A2: Monthly dry-matter balance: forage grown, conserved and bought.
B3: Month | D3: 1 | E3: 2 | F3: 3 | G3: 4 | H3: 5 | I3: 6 | J3: 7 | K3: 8 | L3: 9 | M3: 10 | N3: 11 | O3: 12 | P3: 13 | Q3: 14 | R3: 15 | S3: 16 | T3: 17 | U3: 18 | V3: 19 | W3: 20 | X3: 21 | Y3: 22 | Z3: 23 | AA3: 24 | AB3: 25 | AC3: 26 | AD3: 27 | AE3: 28 | AF3: 29 | AG3: 30 | AH3: 31 | AI3: 32 | AJ3: 33 | AK3: 34 | AL3: 35 | AM3: 36 | AN3: 37 | AO3: 38 | AP3: 39 | AQ3: 40 | AR3: 41 | AS3: 42 | AT3: 43 | AU3: 44 | AV3: 45 | AW3: 46 | AX3: 47 | AY3: 48 | AZ3: 49 | BA3: 50 | BB3: 51 | BC3: 52 | BD3: 53 | BE3: 54 | BF3: 55 | BG3: 56 | BH3: 57 | BI3: 58 | BJ3: 59 | BK3: 60 | BL3: 61 | BM3: 62 | BN3: 63 | BO3: 64 | BP3: 65 | BQ3: 66 | BR3: 67 | BS3: 68 | BT3: 69 | BU3: 70 | BV3: 71 | BW3: 72 | BX3: 73 | BY3: 74 | BZ3: 75 | CA3: 76 | CB3: 77 | CC3: 78 | CD3: 79 | CE3: 80 | CF3: 81 | CG3: 82 | CH3: 83 | CI3: 84 | CJ3: 85 | CK3: 86 | CL3: 87 | CM3: 88 | CN3: 89 | CO3: 90 | CP3: 91 | CQ3: 92 | CR3: 93 | CS3: 94 | CT3: 95 | CU3: 96 | CV3: 97 | CW3: 98 | CX3: 99 | CY3: 100 | CZ3: 101 | DA3: 102 | DB3: 103 | DC3: 104 | DD3: 105 | DE3: 106 | DF3: 107 | DG3: 108 | DH3: 109 | DI3: 110 | DJ3: 111 | DK3: 112 | DL3: 113 | DM3: 114 | DN3: 115 | DO3: 116 | DP3: 117 | DQ3: 118 | DR3: 119 | DS3: 120
B4: Farm year | D4: =INT((D$3-1)/12)+1 | E4: =INT((E$3-1)/12)+1 | F4: =INT((F$3-1)/12)+1 | G4: =INT((G$3-1)/12)+1 | H4: =INT((H$3-1)/12)+1 | I4: =INT((I$3-1)/12)+1 | J4: =INT((J$3-1)/12)+1 | K4: =INT((K$3-1)/12)+1 | ... DS4: =INT((DS$3-1)/12)+1
B5: Calendar month | D5: =MOD(Control!$C$10+D$3-2,12)+1 | E5: =MOD(Control!$C$10+E$3-2,12)+1 | F5: =MOD(Control!$C$10+F$3-2,12)+1 | G5: =MOD(Control!$C$10+G$3-2,12)+1 | H5: =MOD(Control!$C$10+H$3-2,12)+1 | I5: =MOD(Control!$C$10+I$3-2,12)+1 | J5: =MOD(Control!$C$10+J$3-2,12)+1 | K5: =MOD(Control!$C$10+K$3-2,12)+1 | ... DS5: =MOD(Control!$C$10+DS$3-2,12)+1
B6: Month starting | D6: =DATE(Control!$C$9+INT((Control!$C$10+D$3-2)/12),D$5,1) | E6: =DATE(Control!$C$9+INT((Control!$C$10+E$3-2)/12),E$5,1) | F6: =DATE(Control!$C$9+INT((Control!$C$10+F$3-2)/12),F$5,1) | G6: =DATE(Control!$C$9+INT((Control!$C$10+G$3-2)/12),G$5,1) | H6: =DATE(Control!$C$9+INT((Control!$C$10+H$3-2)/12),H$5,1) | I6: =DATE(Control!$C$9+INT((Control!$C$10+I$3-2)/12),I$5,1) | J6: =DATE(Control!$C$9+INT((Control!$C$10+J$3-2)/12),J$5,1) | K6: =DATE(Control!$C$9+INT((Control!$C$10+K$3-2)/12),K$5,1) | ... DS6: =DATE(Control!$C$9+INT((Control!$C$10+DS$3-2)/12),DS$5,1)
